public class ExceptionhandlingTest {
    public static int divide(int[] array, int index) {
        try {
            System.out.println("\nFirst try block in divide() entered");
            array[index + 2] = array[index]/array[index + 1];
            System.out.println("Code at end of first try block in divide()");
            // return array[index + 2];
        } catch(ArithmeticException e) {
            System.err.println(e.getMessage());
            e.printStackTrace();
        } catch(ArrayIndexOutOfBoundsException e) {
            System.err.println("Index-out-of-bounds exception caught in divide()\n"
                    +"\nMessage in exception object:\n\t" + e.getMessage());
            System.err.println("\nStack trace output:\n");
            e.printStackTrace();
            System.out.println("\nEnd of stack trace output\n");
        } finally {
            System.err.println("finally clause in divide()");}
        System.out.println("Executing code after try block in divide()");
        return array[index + 2];
    }

    public static void main(String[] args){

        int[] numberArr = {10,5,0};

        int result = ExceptionhandlingTest.divide(numberArr, 0);

        System.out.println(result);
    }
}